[2024-05-23T17:29:56.774+0000] {local_task_job_runner.py:120} INFO - ::group::Pre task execution logs
[2024-05-23T17:29:56.831+0000] {taskinstance.py:2076} INFO - Dependencies all met for dep_context=non-requeueable deps ti=<TaskInstance: dag_polygon_etl_v02.extract scheduled__2024-05-21T00:00:00+00:00 [queued]>
[2024-05-23T17:29:56.842+0000] {taskinstance.py:2076} INFO - Dependencies all met for dep_context=requeueable deps ti=<TaskInstance: dag_polygon_etl_v02.extract scheduled__2024-05-21T00:00:00+00:00 [queued]>
[2024-05-23T17:29:56.842+0000] {taskinstance.py:2306} INFO - Starting attempt 1 of 6
[2024-05-23T17:29:56.861+0000] {taskinstance.py:2330} INFO - Executing <Task(PythonOperator): extract> on 2024-05-21 00:00:00+00:00
[2024-05-23T17:29:56.872+0000] {standard_task_runner.py:90} INFO - Running: ['***', 'tasks', 'run', 'dag_polygon_etl_v02', 'extract', 'scheduled__2024-05-21T00:00:00+00:00', '--job-id', '14', '--raw', '--subdir', 'DAGS_FOLDER/dag_polygon_etl.py', '--cfg-path', '/tmp/tmp0qu8jrzf']
[2024-05-23T17:29:56.876+0000] {standard_task_runner.py:91} INFO - Job 14: Subtask extract
[2024-05-23T17:29:56.879+0000] {logging_mixin.py:188} WARNING - /home/***/.local/lib/python3.12/site-packages/***/task/task_runner/standard_task_runner.py:61 DeprecationWarning: This process (pid=3899) is multi-threaded, use of fork() may lead to deadlocks in the child.
[2024-05-23T17:29:56.880+0000] {standard_task_runner.py:63} INFO - Started process 3905 to run task
[2024-05-23T17:29:56.936+0000] {task_command.py:426} INFO - Running <TaskInstance: dag_polygon_etl_v02.extract scheduled__2024-05-21T00:00:00+00:00 [running]> on host 46d6b7e1bb4c
[2024-05-23T17:29:57.228+0000] {taskinstance.py:2648} INFO - Exporting env vars: AIRFLOW_CTX_DAG_OWNER='kazik' AIRFLOW_CTX_DAG_ID='dag_polygon_etl_v02' AIRFLOW_CTX_TASK_ID='extract' AIRFLOW_CTX_EXECUTION_DATE='2024-05-21T00:00:00+00:00' AIRFLOW_CTX_TRY_NUMBER='1' AIRFLOW_CTX_DAG_RUN_ID='scheduled__2024-05-21T00:00:00+00:00'
[2024-05-23T17:29:57.229+0000] {taskinstance.py:430} INFO - ::endgroup::
[2024-05-23T17:29:57.256+0000] {taskinstance.py:441} INFO - ::group::Post task execution logs
[2024-05-23T17:29:57.257+0000] {taskinstance.py:2905} ERROR - Task failed with exception
Traceback (most recent call last):
  File "/home/airflow/.local/lib/python3.12/site-packages/urllib3/connection.py", line 198, in _new_conn
    sock = connection.create_connection(
           ^^^^^^^^^^^^^^^^^^^^^^^^^^^^^
  File "/home/airflow/.local/lib/python3.12/site-packages/urllib3/util/connection.py", line 60, in create_connection
    for res in socket.getaddrinfo(host, port, family, socket.SOCK_STREAM):
               ^^^^^^^^^^^^^^^^^^^^^^^^^^^^^^^^^^^^^^^^^^^^^^^^^^^^^^^^^^
  File "/usr/local/lib/python3.12/socket.py", line 963, in getaddrinfo
    for res in _socket.getaddrinfo(host, port, family, type, proto, flags):
               ^^^^^^^^^^^^^^^^^^^^^^^^^^^^^^^^^^^^^^^^^^^^^^^^^^^^^^^^^^^
socket.gaierror: [Errno -3] Temporary failure in name resolution

The above exception was the direct cause of the following exception:

Traceback (most recent call last):
  File "/home/airflow/.local/lib/python3.12/site-packages/urllib3/connectionpool.py", line 793, in urlopen
    response = self._make_request(
               ^^^^^^^^^^^^^^^^^^^
  File "/home/airflow/.local/lib/python3.12/site-packages/urllib3/connectionpool.py", line 491, in _make_request
    raise new_e
  File "/home/airflow/.local/lib/python3.12/site-packages/urllib3/connectionpool.py", line 467, in _make_request
    self._validate_conn(conn)
  File "/home/airflow/.local/lib/python3.12/site-packages/urllib3/connectionpool.py", line 1099, in _validate_conn
    conn.connect()
  File "/home/airflow/.local/lib/python3.12/site-packages/urllib3/connection.py", line 616, in connect
    self.sock = sock = self._new_conn()
                       ^^^^^^^^^^^^^^^^
  File "/home/airflow/.local/lib/python3.12/site-packages/urllib3/connection.py", line 205, in _new_conn
    raise NameResolutionError(self.host, self, e) from e
urllib3.exceptions.NameResolutionError: <urllib3.connection.HTTPSConnection object at 0x7b2c31c4fd10>: Failed to resolve 'api.polygon.io' ([Errno -3] Temporary failure in name resolution)

The above exception was the direct cause of the following exception:

Traceback (most recent call last):
  File "/home/airflow/.local/lib/python3.12/site-packages/requests/adapters.py", line 486, in send
    resp = conn.urlopen(
           ^^^^^^^^^^^^^
  File "/home/airflow/.local/lib/python3.12/site-packages/urllib3/connectionpool.py", line 847, in urlopen
    retries = retries.increment(
              ^^^^^^^^^^^^^^^^^^
  File "/home/airflow/.local/lib/python3.12/site-packages/urllib3/util/retry.py", line 515, in increment
    raise MaxRetryError(_pool, url, reason) from reason  # type: ignore[arg-type]
    ^^^^^^^^^^^^^^^^^^^^^^^^^^^^^^^^^^^^^^^^^^^^^^^^^^^
urllib3.exceptions.MaxRetryError: HTTPSConnectionPool(host='api.polygon.io', port=443): Max retries exceeded with url: /v3/reference/tickers/types?apiKey=BH1TqYfUvL6xV1YWnpVdxiXYYZsikHM8 (Caused by NameResolutionError("<urllib3.connection.HTTPSConnection object at 0x7b2c31c4fd10>: Failed to resolve 'api.polygon.io' ([Errno -3] Temporary failure in name resolution)"))

During handling of the above exception, another exception occurred:

Traceback (most recent call last):
  File "/home/airflow/.local/lib/python3.12/site-packages/airflow/models/taskinstance.py", line 465, in _execute_task
    result = _execute_callable(context=context, **execute_callable_kwargs)
             ^^^^^^^^^^^^^^^^^^^^^^^^^^^^^^^^^^^^^^^^^^^^^^^^^^^^^^^^^^^^^
  File "/home/airflow/.local/lib/python3.12/site-packages/airflow/models/taskinstance.py", line 432, in _execute_callable
    return execute_callable(context=context, **execute_callable_kwargs)
           ^^^^^^^^^^^^^^^^^^^^^^^^^^^^^^^^^^^^^^^^^^^^^^^^^^^^^^^^^^^^
  File "/home/airflow/.local/lib/python3.12/site-packages/airflow/models/baseoperator.py", line 400, in wrapper
    return func(self, *args, **kwargs)
           ^^^^^^^^^^^^^^^^^^^^^^^^^^^
  File "/home/airflow/.local/lib/python3.12/site-packages/airflow/operators/python.py", line 235, in execute
    return_value = self.execute_callable()
                   ^^^^^^^^^^^^^^^^^^^^^^^
  File "/home/airflow/.local/lib/python3.12/site-packages/airflow/operators/python.py", line 252, in execute_callable
    return self.python_callable(*self.op_args, **self.op_kwargs)
           ^^^^^^^^^^^^^^^^^^^^^^^^^^^^^^^^^^^^^^^^^^^^^^^^^^^^^
  File "/opt/airflow/dags/extract/client.py", line 17, in wrapper
    response = func(self, *args)
               ^^^^^^^^^^^^^^^^^
  File "/opt/airflow/dags/extract/client.py", line 62, in get_all_ticker_types
    return requests.get(
           ^^^^^^^^^^^^^
  File "/home/airflow/.local/lib/python3.12/site-packages/requests/api.py", line 73, in get
    return request("get", url, params=params, **kwargs)
           ^^^^^^^^^^^^^^^^^^^^^^^^^^^^^^^^^^^^^^^^^^^^
  File "/home/airflow/.local/lib/python3.12/site-packages/requests/api.py", line 59, in request
    return session.request(method=method, url=url, **kwargs)
           ^^^^^^^^^^^^^^^^^^^^^^^^^^^^^^^^^^^^^^^^^^^^^^^^^
  File "/home/airflow/.local/lib/python3.12/site-packages/requests/sessions.py", line 589, in request
    resp = self.send(prep, **send_kwargs)
           ^^^^^^^^^^^^^^^^^^^^^^^^^^^^^^
  File "/home/airflow/.local/lib/python3.12/site-packages/requests/sessions.py", line 703, in send
    r = adapter.send(request, **kwargs)
        ^^^^^^^^^^^^^^^^^^^^^^^^^^^^^^^
  File "/home/airflow/.local/lib/python3.12/site-packages/requests/adapters.py", line 519, in send
    raise ConnectionError(e, request=request)
requests.exceptions.ConnectionError: HTTPSConnectionPool(host='api.polygon.io', port=443): Max retries exceeded with url: /v3/reference/tickers/types?apiKey=BH1TqYfUvL6xV1YWnpVdxiXYYZsikHM8 (Caused by NameResolutionError("<urllib3.connection.HTTPSConnection object at 0x7b2c31c4fd10>: Failed to resolve 'api.polygon.io' ([Errno -3] Temporary failure in name resolution)"))
[2024-05-23T17:29:57.274+0000] {taskinstance.py:1206} INFO - Marking task as UP_FOR_RETRY. dag_id=dag_polygon_etl_v02, task_id=extract, run_id=scheduled__2024-05-21T00:00:00+00:00, execution_date=20240521T000000, start_date=20240523T172956, end_date=20240523T172957
[2024-05-23T17:29:57.291+0000] {standard_task_runner.py:110} ERROR - Failed to execute job 14 for task extract (HTTPSConnectionPool(host='api.polygon.io', port=443): Max retries exceeded with url: /v3/reference/tickers/types?apiKey=BH1TqYfUvL6xV1YWnpVdxiXYYZsikHM8 (Caused by NameResolutionError("<urllib3.connection.HTTPSConnection object at 0x7b2c31c4fd10>: Failed to resolve 'api.polygon.io' ([Errno -3] Temporary failure in name resolution)")); 3905)
[2024-05-23T17:29:57.336+0000] {local_task_job_runner.py:240} INFO - Task exited with return code 1
[2024-05-23T17:29:57.350+0000] {logging_mixin.py:188} WARNING - /home/***/.local/lib/python3.12/site-packages/***/models/baseoperator.py:1296 AirflowProviderDeprecationWarning: Call to deprecated class MsSqlOperator. (Please use `***.providers.common.sql.operators.sql.SQLExecuteQueryOperator`.Also, you can provide `hook_params={'schema': <database>}`.)
[2024-05-23T17:29:57.353+0000] {local_task_job_runner.py:222} INFO - ::endgroup::
